<?xml version="1.0" ?>
<!-- =================================================================================== -->
<!-- |    This document was autogenerated by xacro from mbot.urdf.xacro                | -->
<!-- |    EDITING THIS FILE BY HAND IS NOT RECOMMENDED                                 | -->
<!-- =================================================================================== -->
<robot name="mbot">
  <!-- /////////////////////////////////////    COLOR    ///////////////////////////////////////////// -->
  <material name="Black">
    <color rgba="0 0 0 1"/>
  </material>
  <material name="White">
    <color rgba="1 1 1 0.95"/>
  </material>
  <material name="Blue">
    <color rgba="0 0 1 1"/>
  </material>
  <material name="Yellow">
    <color rgba="1 0.4 0 1"/>
  </material>
  <!-- Base link -->
  <link name="base_link">
    <visual>
      <origin rpy="0 0 0" xyz="0 0 0"/>
      <geometry>
        <cylinder length="0.04" radius="0.05"/>
      </geometry>
      <material name="Yellow"/>
    </visual>
    <collision>
      <origin rpy="0 0 0" xyz="0 0 0"/>
      <geometry>
        <cylinder length="0.04" radius="0.05"/>
      </geometry>
    </collision>
    <inertial>
      <mass value="1.0"/>
      <inertia ixx="0.0007583333333333335" ixy="0" ixz="0" iyy="0.0007583333333333335" iyz="0" izz="0.0012500000000000002"/>
    </inertial>
  </link>
  <!-- Left wheel link -->
  <link name="left_wheel_link">
    <visual>
      <origin rpy="1.5707 0 0" xyz="0 0 0"/>
      <geometry>
        <cylinder length="0.00625" radius="0.015"/>
      </geometry>
      <material name="White"/>
    </visual>
    <collision>
      <origin rpy="1.5707 0 0" xyz="0 0 0"/>
      <geometry>
        <cylinder length="0.00625" radius="0.015"/>
      </geometry>
    </collision>
    <inertial>
      <mass value="0.1"/>
      <inertia ixx="5.950520833333333e-06" ixy="0" ixz="0" iyy="5.950520833333333e-06" iyz="0" izz="1.1249999999999999e-05"/>
    </inertial>
  </link>
  <joint name="left_wheel_joint" type="continuous">
    <origin rpy="0 0 0" xyz="0 0.0475 -0.0125"/>
    <parent link="base_link"/>
    <child link="left_wheel_link"/>
    <axis xyz="0 1 0"/>
  </joint>
  <!-- Right wheel link -->
  <link name="right_wheel_link">
    <visual>
      <origin rpy="1.5707 0 0" xyz="0 0 0"/>
      <geometry>
        <cylinder length="0.00625" radius="0.015"/>
      </geometry>
      <material name="White"/>
    </visual>
    <collision>
      <origin rpy="1.5707 0 0" xyz="0 0 0"/>
      <geometry>
        <cylinder length="0.00625" radius="0.015"/>
      </geometry>
    </collision>
    <inertial>
      <mass value="0.1"/>
      <inertia ixx="5.950520833333333e-06" ixy="0" ixz="0" iyy="5.950520833333333e-06" iyz="0" izz="1.1249999999999999e-05"/>
    </inertial>
  </link>
  <joint name="right_wheel_joint" type="continuous">
    <origin rpy="0 0 0" xyz="0 -0.0475 -0.0125"/>
    <parent link="base_link"/>
    <child link="right_wheel_link"/>
    <axis xyz="0 1 0"/>
  </joint>
  <!-- Front caster link -->
  <link name="front_caster_link">
    <visual>
      <origin rpy="0 0 0" xyz="0 0 0"/>
      <geometry>
        <sphere radius="0.00375"/>
      </geometry>
      <material name="Black"/>
    </visual>
    <collision>
      <origin rpy="0 0 0" xyz="0 0 0"/>
      <geometry>
        <sphere radius="0.00375"/>
      </geometry>
    </collision>
    <inertial>
      <mass value="0.05"/>
      <inertia ixx="2.8124999999999995e-07" ixy="0" ixz="0" iyy="2.8124999999999995e-07" iyz="0" izz="2.8124999999999995e-07"/>
    </inertial>
  </link>
  <joint name="front_caster_joint" type="fixed">
    <origin rpy="0 0 0" xyz="0.045 0 -0.02375"/>
    <parent link="base_link"/>
    <child link="front_caster_link"/>
  </joint>
  <!-- Back caster link -->
  <link name="back_caster_link">
    <visual>
      <origin rpy="0 0 0" xyz="0 0 0"/>
      <geometry>
        <sphere radius="0.00375"/>
      </geometry>
      <material name="Black"/>
    </visual>
    <collision>
      <origin rpy="0 0 0" xyz="0 0 0"/>
      <geometry>
        <sphere radius="0.00375"/>
      </geometry>
    </collision>
    <inertial>
      <mass value="0.05"/>
      <inertia ixx="2.8124999999999995e-07" ixy="0" ixz="0" iyy="2.8124999999999995e-07" iyz="0" izz="2.8124999999999995e-07"/>
    </inertial>
  </link>
  <joint name="back_caster_joint" type="fixed">
    <origin rpy="0 0 0" xyz="-0.045 0 -0.02375"/>
    <parent link="base_link"/>
    <child link="back_caster_link"/>
  </joint>
  <gazebo>
    <plugin filename="libgazebo_ros_diff_drive.so" name="differential_drive_controller">
      <legacyMode>false</legacyMode>
      <publishWheelTF>true</publishWheelTF>
      <publishWheelJointState>true</publishWheelJointState>
      <robotNamespace>/mbot</robotNamespace>
      <commandTopic>cmd_vel</commandTopic>
      <odometryTopic>odom</odometryTopic>
      <odometryFrame>odom</odometryFrame>
      <robotBaseFrame>base_link</robotBaseFrame>
      <wheelSeparation>0.095</wheelSeparation>
      <wheelDiameter>0.03</wheelDiameter>
      <wheelAcceleration>1.0</wheelAcceleration>
      <wheelTorque>10.0</wheelTorque>
    </plugin>
  </gazebo>
</robot>

